Workbook

Sheet Raw_Data
A1: Employee_ID | B1: Age | C1: Gender | D1: Department | E1: Job_Role | F1: Education | G1: Years_of_Experience | H1: Monthly_Salary | I1: Performance_Rating | J1: Job_Satisfaction | K1: Overtime | L1: Attendance_Percentage | M1: Years_at_Company | N1: Attrition
A2: EMP0001 | B2: 36 | C2: Female | D2: Finance | E2: Financial Analyst | F2: Diploma | G2: 5 | H2: 58235 | I2: 3 | J2: 2 | K2: No | L2: 95.9 | M2: 2 | N2: No
A3: EMP0002 | B3: 43 | C3: Male | D3: HR | E3: HR Executive | F3: Bachelor's | G3: 14 | H3: 54400 | I3: 3 | J3: 2 | K3: No | L3: 91.2 | M3: 8 | N3: No
A4: EMP0003 | B4: 31 | C4: Male | D4: Sales | E4: Account Manager | F4: Master's | G4: 7 | H4: 62751 | I4: 2 | J4: 3 | K4: Yes | L4: 91.4 | M4: 2 | N4: No
A5: EMP0004 | B5: 27 | C5: Male | D5: Marketing | E5: Content Specialist | F5: Master's | G5: 5 | H5: 49837 | I5: 3 | J5: 3 | K5: Yes | L5: 96.4 | M5: 3 | N5: Yes
A6: EMP0005 | B6: 39 | C6: Female | D6: Finance | E6: Accountant | F6: Master's | G6: 11 | H6: 62344 | I6: 3 | J6: 4 | K6: No | L6: 96.8 | M6: 4 | N6: No
A7: EMP0006 | B7: 31 | C7: Male | D7: HR | E7: Recruiter | F7: Bachelor's | G7: 6 | H7: 45550 | I7: 3 | J7: 3 | K7: No | L7: 86.3 | M7: 2 | N7: No
A8: EMP0007 | B8: 37 | C8: Female | D8: HR | E8: HR Manager | F8: Master's | G8: 10 | H8: 65427 | I8: 2 | J8: 2 | K8: Yes | L8: 86 | M8: 4 | N8: No
A9: EMP0008 | B9: 30 | C9: Male | D9: Finance | E9: Finance Manager | F9: Bachelor's | G9: 5 | H9: 74306 | I9: 3 | J9: 1 | K9: Yes | L9: 85.4 | M9: 2 | N9: No
A10: EMP0009 | B10: 37 | C10: Male | D10: Operations | E10: Operations Executive | F10: Master's | G10: 6 | H10: 48578 | I10: 2 | J10: 2 | K10: No | L10: 83.4 | M10: 1 | N10: No
A11: EMP0010 | B11: 35 | C11: Female | D11: Marketing | E11: Content Specialist | F11: Master's | G11: 6 | H11: 53487 | I11: 4 | J11: 2 | K11: Yes | L11: 92.9 | M11: 3 | N11: Yes
A12: EMP0011 | B12: 44 | C12: Male | D12: Sales | E12: Sales Executive | F12: Bachelor's | G12: 16 | H12: 57840 | I12: 2 | J12: 3 | K12: Yes | L12: 84.6 | M12: 6 | N12: No
A13: EMP0012 | B13: 36 | C13: Male | D13: Engineering | E13: QA Engineer | F13: Diploma | G13: 11 | H13: 66371 | I13: 3 | J13: 2 | K13: No | L13: 88.9 | M13: 3 | N13: Yes
... A101: EMP0100 | B101: 38 | C101: Female | D101: HR | E101: HR Executive | F101: Master's | G101: 12 | H101: 48308 | I101: 2 | J101: 3 | K101: No | L101: 88 | M101: 4 | N101: No

Sheet Cleaned_Data
A1: Employee_ID | B1: Age | C1: Gender | D1: Department | E1: Job_Role | F1: Education | G1: Years_of_Experience | H1: Monthly_Salary | I1: Performance_Rating | J1: Job_Satisfaction | K1: Overtime | L1: Attendance_Percentage | M1: Years_at_Company | N1: Attrition | P1: Data Quality Checks
A2: EMP0001 | B2: 36 | C2: Female | D2: Finance | E2: Financial Analyst | F2: Diploma | G2: 5 | H2: 58235 | I2: 3 | J2: 2 | K2: No | L2: 95.9 | M2: 2 | N2: No | P2: Total rows | Q2: =COUNTA(A2:A101) -> 100
A3: EMP0002 | B3: 43 | C3: Male | D3: HR | E3: HR Executive | F3: Bachelor's | G3: 14 | H3: 54400 | I3: 3 | J3: 2 | K3: No | L3: 91.2 | M3: 8 | N3: No | P3: Missing Employee_ID | Q3: =COUNTBLANK(A2:A101) -> 0
A4: EMP0003 | B4: 31 | C4: Male | D4: Sales | E4: Account Manager | F4: Master's | G4: 7 | H4: 62751 | I4: 2 | J4: 3 | K4: Yes | L4: 91.4 | M4: 2 | N4: No | P4: Missing Monthly_Salary | Q4: =COUNTBLANK(H2:H101) -> 0
A5: EMP0004 | B5: 27 | C5: Male | D5: Marketing | E5: Content Specialist | F5: Master's | G5: 5 | H5: 49837 | I5: 3 | J5: 3 | K5: Yes | L5: 96.4 | M5: 3 | N5: Yes | P5: Duplicate Employee_IDs | Q5: =SUMPRODUCT((COUNTIF(A2:A101,A2:A101)>1)*1) -> 0
A6: EMP0005 | B6: 39 | C6: Female | D6: Finance | E6: Accountant | F6: Master's | G6: 11 | H6: 62344 | I6: 3 | J6: 4 | K6: No | L6: 96.8 | M6: 4 | N6: No
A7: EMP0006 | B7: 31 | C7: Male | D7: HR | E7: Recruiter | F7: Bachelor's | G7: 6 | H7: 45550 | I7: 3 | J7: 3 | K7: No | L7: 86.3 | M7: 2 | N7: No | P7: Checked for missing values, duplicate IDs, and duplicate rows. This is a clean synthetic dataset — zero issues found.
A8: EMP0007 | B8: 37 | C8: Female | D8: HR | E8: HR Manager | F8: Master's | G8: 10 | H8: 65427 | I8: 2 | J8: 2 | K8: Yes | L8: 86 | M8: 4 | N8: No
A9: EMP0008 | B9: 30 | C9: Male | D9: Finance | E9: Finance Manager | F9: Bachelor's | G9: 5 | H9: 74306 | I9: 3 | J9: 1 | K9: Yes | L9: 85.4 | M9: 2 | N9: No
A10: EMP0009 | B10: 37 | C10: Male | D10: Operations | E10: Operations Executive | F10: Master's | G10: 6 | H10: 48578 | I10: 2 | J10: 2 | K10: No | L10: 83.4 | M10: 1 | N10: No
A11: EMP0010 | B11: 35 | C11: Female | D11: Marketing | E11: Content Specialist | F11: Master's | G11: 6 | H11: 53487 | I11: 4 | J11: 2 | K11: Yes | L11: 92.9 | M11: 3 | N11: Yes
A12: EMP0011 | B12: 44 | C12: Male | D12: Sales | E12: Sales Executive | F12: Bachelor's | G12: 16 | H12: 57840 | I12: 2 | J12: 3 | K12: Yes | L12: 84.6 | M12: 6 | N12: No
A13: EMP0012 | B13: 36 | C13: Male | D13: Engineering | E13: QA Engineer | F13: Diploma | G13: 11 | H13: 66371 | I13: 3 | J13: 2 | K13: No | L13: 88.9 | M13: 3 | N13: Yes
A14: EMP0013 | B14: 42 | C14: Male | D14: HR | E14: HR Executive | F14: Master's | G14: 13 | H14: 60771 | I14: 3 | J14: 4 | K14: No | L14: 86.1 | M14: 6 | N14: Yes
A15: EMP0014 | B15: 28 | C15: Female | D15: Marketing | E15: Marketing Executive | F15: Bachelor's | G15: 7 | H15: 55839 | I15: 3 | J15: 3 | K15: No | L15: 94.2 | M15: 5 | N15: Yes
A16: EMP0015 | B16: 24 | C16: Female | D16: Marketing | E16: Content Specialist | F16: PhD | G16: 0 | H16: 53224 | I16: 3 | J16: 2 | K16: No | L16: 94.1 | M16: 0 | N16: No
A17: EMP0016 | B17: 35 | C17: Male | D17: Sales | E17: Account Manager | F17: Master's | G17: 4 | H17: 60567 | I17: 4 | J17: 2 | K17: No | L17: 95.2 | M17: 1 | N17: No
A18: EMP0017 | B18: 33 | C18: Male | D18: Engineering | E18: Senior Engineer | F18: Master's | G18: 6 | H18: 89705 | I18: 2 | J18: 1 | K18: Yes | L18: 90.3 | M18: 0 | N18: No
A19: EMP0018 | B19: 23 | C19: Male | D19: Operations | E19: Operations Executive | F19: Bachelor's | G19: 1 | H19: 48911 | I19: 3 | J19: 4 | K19: Yes | L19: 88.5 | M19: 0 | N19: Yes
... A101: EMP0100 | B101: 38 | C101: Female | D101: HR | E101: HR Executive | F101: Master's | G101: 12 | H101: 48308 | I101: 2 | J101: 3 | K101: No | L101: 88 | M101: 4 | N101: No

Sheet Analysis
B2: HR Employee Analytics — Business Question Answers
B3: All values below are calculated with live formulas referencing Cleaned_Data.
B5: # | C5: Answer
B6: 1. How many employees are there? | C6: =COUNTA(tblHRDataClean[Employee_ID]) -> 100
B7: 2. What is the average monthly salary? | C7: =ROUND(AVERAGE(tblHRDataClean[Monthly_Salary]),0) -> 62972
B8: 3. Which department has the most employees? (count shown; see PivotTables for name) | C8: =INDEX(B20:B25,MATCH(MAX(C20:C25),C20:C25,0))&" ("&MAX(C20:C25)&" employees)" -> Engineering (24 employees)
B9: 4. Highest department average salary (value; see PivotTables for department name) | C9: =INDEX(B20:B25,MATCH(MAX(D20:D25),D20:D25,0))&" (avg "&TEXT(MAX(D20:D25),"#,##0")&")" -> Engineering (avg 81,527)
B10: 5. What % of employees work overtime? | C10: =ROUND(COUNTIF(tblHRDataClean[Overtime],"Yes")/COUNTA(tblHRDataClean[Overtime]),4) -> 0.37
B11: 6. Highest-attrition department (rate; see PivotTables for department name) | C11: =INDEX(B20:B25,MATCH(MAX(E20:E25),E20:E25,0))&" ("&TEXT(MAX(E20:E25),"0.0%")&")" -> Marketing (35.7%)
B12: 7. What is the average job satisfaction score (1-5)? | C12: =ROUND(AVERAGE(tblHRDataClean[Job_Satisfaction]),2) -> 2.67
B13: 8. What is the average performance rating (1-5)? | C13: =ROUND(AVERAGE(tblHRDataClean[Performance_Rating]),2) -> 2.73
B14: 9. What % of employees have a high performance rating (4 or 5)? | C14: =ROUND(COUNTIF(tblHRDataClean[Performance_Rating],">=4")/COUNTA(tblHRDataClean[Performance_Rating]),4) -> 0.19
B15: 10. Overall attrition rate (% of employees who left) | C15: =ROUND(COUNTIF(tblHRDataClean[Attrition],"Yes")/COUNTA(tblHRDataClean[Attrition]),4) -> 0.19
B18: Department Helper Table (used for Q3, Q4, Q6)
B19: Department | C19: Employee Count | D19: Avg Salary | E19: Attrition Rate
B20: Engineering | C20: =COUNTIF(tblHRDataClean[Department],B20) -> 24 | D20: =ROUND(AVERAGEIF(tblHRDataClean[Department],B20,tblHRDataClean[Monthly_Salary]),0) -> 81527 | E20: =ROUND(COUNTIFS(tblHRDataClean[Department],B20,tblHRDataClean[Attrition],"Yes")/COUNTIF(tblHRDataClean[Department],B20),4) -> 0.25
B21: Finance | C21: =COUNTIF(tblHRDataClean[Department],B21) -> 14 | D21: =ROUND(AVERAGEIF(tblHRDataClean[Department],B21,tblHRDataClean[Monthly_Salary]),0) -> 61099 | E21: =ROUND(COUNTIFS(tblHRDataClean[Department],B21,tblHRDataClean[Attrition],"Yes")/COUNTIF(tblHRDataClean[Department],B21),4) -> 0
B22: HR | C22: =COUNTIF(tblHRDataClean[Department],B22) -> 12 | D22: =ROUND(AVERAGEIF(tblHRDataClean[Department],B22,tblHRDataClean[Monthly_Salary]),0) -> 54089 | E22: =ROUND(COUNTIFS(tblHRDataClean[Department],B22,tblHRDataClean[Attrition],"Yes")/COUNTIF(tblHRDataClean[Department],B22),4) -> 0.1667
B23: Marketing | C23: =COUNTIF(tblHRDataClean[Department],B23) -> 14 | D23: =ROUND(AVERAGEIF(tblHRDataClean[Department],B23,tblHRDataClean[Monthly_Salary]),0) -> 58822 | E23: =ROUND(COUNTIFS(tblHRDataClean[Department],B23,tblHRDataClean[Attrition],"Yes")/COUNTIF(tblHRDataClean[Department],B23),4) -> 0.3571
B24: Operations | C24: =COUNTIF(tblHRDataClean[Department],B24) -> 16 | D24: =ROUND(AVERAGEIF(tblHRDataClean[Department],B24,tblHRDataClean[Monthly_Salary]),0) -> 53207 | E24: =ROUND(COUNTIFS(tblHRDataClean[Department],B24,tblHRDataClean[Attrition],"Yes")/COUNTIF(tblHRDataClean[Department],B24),4) -> 0.125
B25: Sales | C25: =COUNTIF(tblHRDataClean[Department],B25) -> 20 | D25: =ROUND(AVERAGEIF(tblHRDataClean[Department],B25,tblHRDataClean[Monthly_Salary]),0) -> 58062 | E25: =ROUND(COUNTIFS(tblHRDataClean[Department],B25,tblHRDataClean[Attrition],"Yes")/COUNTIF(tblHRDataClean[Department],B25),4) -> 0.2

Sheet PivotTables
B2: Pivot-Style Summary Tables
B3: Built with SUMIFS / COUNTIFS / AVERAGEIFS formulas referencing Cleaned_Data.
B5: 1. Employee Count by Department
B6: Department | C6: Employee Count
B7: Engineering | C7: =COUNTIF(tblHRDataClean[Department],"Engineering") -> 24
B8: Finance | C8: =COUNTIF(tblHRDataClean[Department],"Finance") -> 14
B9: HR | C9: =COUNTIF(tblHRDataClean[Department],"HR") -> 12
B10: Marketing | C10: =COUNTIF(tblHRDataClean[Department],"Marketing") -> 14
B11: Operations | C11: =COUNTIF(tblHRDataClean[Department],"Operations") -> 16
B12: Sales | C12: =COUNTIF(tblHRDataClean[Department],"Sales") -> 20
B15: 2. Attrition by Department
B16: Department | C16: Left (Count) | D16: Attrition Rate
B17: Engineering | C17: =COUNTIFS(tblHRDataClean[Department],"Engineering",tblHRDataClean[Attrition],"Yes") -> 6 | D17: =ROUND(COUNTIFS(tblHRDataClean[Department],"Engineering",tblHRDataClean[Attrition],"Yes")/COUNTIF(tblHRDataClean[Department],"Engineering"),4) -> 0.25
B18: Finance | C18: =COUNTIFS(tblHRDataClean[Department],"Finance",tblHRDataClean[Attrition],"Yes") -> 0 | D18: =ROUND(COUNTIFS(tblHRDataClean[Department],"Finance",tblHRDataClean[Attrition],"Yes")/COUNTIF(tblHRDataClean[Department],"Finance"),4) -> 0
B19: HR | C19: =COUNTIFS(tblHRDataClean[Department],"HR",tblHRDataClean[Attrition],"Yes") -> 2 | D19: =ROUND(COUNTIFS(tblHRDataClean[Department],"HR",tblHRDataClean[Attrition],"Yes")/COUNTIF(tblHRDataClean[Department],"HR"),4) -> 0.1667
B20: Marketing | C20: =COUNTIFS(tblHRDataClean[Department],"Marketing",tblHRDataClean[Attrition],"Yes") -> 5 | D20: =ROUND(COUNTIFS(tblHRDataClean[Department],"Marketing",tblHRDataClean[Attrition],"Yes")/COUNTIF(tblHRDataClean[Department],"Marketing"),4) -> 0.3571
B21: Operations | C21: =COUNTIFS(tblHRDataClean[Department],"Operations",tblHRDataClean[Attrition],"Yes") -> 2 | D21: =ROUND(COUNTIFS(tblHRDataClean[Department],"Operations",tblHRDataClean[Attrition],"Yes")/COUNTIF(tblHRDataClean[Department],"Operations"),4) -> 0.125
B22: Sales | C22: =COUNTIFS(tblHRDataClean[Department],"Sales",tblHRDataClean[Attrition],"Yes") -> 4 | D22: =ROUND(COUNTIFS(tblHRDataClean[Department],"Sales",tblHRDataClean[Attrition],"Yes")/COUNTIF(tblHRDataClean[Department],"Sales"),4) -> 0.2
B25: 3. Average Salary by Department
B26: Department | C26: Avg Monthly Salary
B27: Engineering | C27: =ROUND(AVERAGEIF(tblHRDataClean[Department],"Engineering",tblHRDataClean[Monthly_Salary]),0) -> 81527
B28: Finance | C28: =ROUND(AVERAGEIF(tblHRDataClean[Department],"Finance",tblHRDataClean[Monthly_Salary]),0) -> 61099
B29: HR | C29: =ROUND(AVERAGEIF(tblHRDataClean[Department],"HR",tblHRDataClean[Monthly_Salary]),0) -> 54089
B30: Marketing | C30: =ROUND(AVERAGEIF(tblHRDataClean[Department],"Marketing",tblHRDataClean[Monthly_Salary]),0) -> 58822
B31: Operations | C31: =ROUND(AVERAGEIF(tblHRDataClean[Department],"Operations",tblHRDataClean[Monthly_Salary]),0) -> 53207
B32: Sales | C32: =ROUND(AVERAGEIF(tblHRDataClean[Department],"Sales",tblHRDataClean[Monthly_Salary]),0) -> 58062
B35: 4. Average Salary by Performance Rating
B36: Performance Rating | C36: Avg Monthly Salary | D36: Employee Count
B37: 1 | C37: =ROUND(AVERAGEIF(tblHRDataClean[Performance_Rating],1,tblHRDataClean[Monthly_Salary]),0) -> 66320 | D37: =COUNTIF(tblHRDataClean[Performance_Rating],1) -> 9
B38: 2 | C38: =ROUND(AVERAGEIF(tblHRDataClean[Performance_Rating],2,tblHRDataClean[Monthly_Salary]),0) -> 60490 | D38: =COUNTIF(tblHRDataClean[Performance_Rating],2) -> 31
B39: 3 | C39: =ROUND(AVERAGEIF(tblHRDataClean[Performance_Rating],3,tblHRDataClean[Monthly_Salary]),0) -> 61185 | D39: =COUNTIF(tblHRDataClean[Performance_Rating],3) -> 41
B40: 4 | C40: =ROUND(AVERAGEIF(tblHRDataClean[Performance_Rating],4,tblHRDataClean[Monthly_Salary]),0) -> 64522 | D40: =COUNTIF(tblHRDataClean[Performance_Rating],4) -> 16
B41: 5 | C41: =ROUND(AVERAGEIF(tblHRDataClean[Performance_Rating],5,tblHRDataClean[Monthly_Salary]),0) -> 94720 | D41: =COUNTIF(tblHRDataClean[Performance_Rating],5) -> 3
B44: 5. Attrition by Overtime Status
B45: Overtime | C45: Employee Count | D45: Left (Count) | E45: Attrition Rate
B46: Yes | C46: =COUNTIF(tblHRDataClean[Overtime],"Yes") -> 37 | D46: =COUNTIFS(tblHRDataClean[Overtime],"Yes",tblHRDataClean[Attrition],"Yes") -> 9 | E46: =ROUND(COUNTIFS(tblHRDataClean[Overtime],"Yes",tblHRDataClean[Attrition],"Yes")/COUNTIF(tblHRDataClean[Overtime],"Yes"),4) -> 0.2432
B47: No | C47: =COUNTIF(tblHRDataClean[Overtime],"No") -> 63 | D47: =COUNTIFS(tblHRDataClean[Overtime],"No",tblHRDataClean[Attrition],"Yes") -> 10 | E47: =ROUND(COUNTIFS(tblHRDataClean[Overtime],"No",tblHRDataClean[Attrition],"Yes")/COUNTIF(tblHRDataClean[Overtime],"No"),4) -> 0.1587
B50: 6. Attrition by Job Satisfaction Level
B51: Satisfaction (1-5) | C51: Employee Count | D51: Left (Count) | E51: Attrition Rate
B52: 1 | C52: =COUNTIF(tblHRDataClean[Job_Satisfaction],1) -> 11 | D52: =COUNTIFS(tblHRDataClean[Job_Satisfaction],1,tblHRDataClean[Attrition],"Yes") -> 3 | E52: =ROUND(COUNTIFS(tblHRDataClean[Job_Satisfaction],1,tblHRDataClean[Attrition],"Yes")/COUNTIF(tblHRDataClean[Job_Satisfaction],1),4) -> 0.2727
...

Sheet Dashboard
B2: HR Employee Analytics — Dashboard
B3: Synthetic / demo data — for learning purposes only.
B5: Total Employees | D5: Attrition Rate | F5: Avg Monthly Salary | H5: Avg Job Satisfaction | J5: Avg Performance Rating | L5: Overtime %
B6: =Analysis!C6 -> 100 | D6: =Analysis!C15 -> 0.19 | F6: =Analysis!C7 -> 62972 | H6: =Analysis!C12 -> 2.67 | J6: =Analysis!C13 -> 2.73 | L6: =Analysis!C10 -> 0.37

Sheet Insights
B2: Business Insights
B3: Based on this synthetic 100-employee dataset only. Patterns here reflect how the demo data was generated, not real-world HR causation. OBSERVATION = what the numbers show. POSSIBLE EXPLANATION = a plausible reason, not a proven cause.
B5: Headcount
B6: OBSERVATION | C6: Engineering is the largest department with 24 employees, followed by Sales (20). HR is the smallest at 12.
B7: POSSIBLE EXPLANATION | C7: Larger technical/production functions like Engineering often carry more headcount than support functions like HR in many organizations.
B9: Attrition — overall
B10: OBSERVATION | C10: The overall attrition rate is 19% (19 of 100 employees marked as having left).
B11: POSSIBLE EXPLANATION | C11: N/A — this is a baseline figure, not yet a pattern to explain.
B13: Attrition — by department
B14: OBSERVATION | C14: Marketing has the highest attrition rate at 35.7%, followed by Engineering at 25%. Finance has 0% attrition in this dataset.
B15: POSSIBLE EXPLANATION | C15: Departments with higher attrition may be worth investigating for workload, compensation, or engagement issues — but with only 12-24 employees per department, a handful of leavers can swing the percentage heavily, so this should not be read as a strong signal on its own.
B17: Salary — by department
B18: OBSERVATION | C18: Engineering has the highest average monthly salary (81,527), while Operations has the lowest (53,207).
B19: POSSIBLE EXPLANATION | C19: Pay differences often track role scarcity and required skill level, which commonly runs higher in technical departments.
B21: Overtime and attrition
B22: OBSERVATION | C22: Employees working overtime have a 24.3% attrition rate, compared to 15.9% for those who do not work overtime.
B23: POSSIBLE EXPLANATION | C23: This is directionally consistent with overtime contributing to burnout and turnover, but the gap (24.3% vs 15.9%) is based on small sample sizes (37 vs 63 employees) and should be treated as a mild signal, not proof.
B25: Satisfaction and attrition
B26: OBSERVATION | C26: Attrition is highest at the lowest satisfaction level (1 = 27.3%) and near-zero at the highest satisfaction level (5 = 0%), but the middle levels do not fall in a perfectly straight line (level 3 is 19.1%, level 4 is 20%).
B27: POSSIBLE EXPLANATION | C27: The overall direction (lower satisfaction, higher attrition) fits common HR expectations, but the noisy middle values are a reminder that this is synthetic data with intentional randomness, not a clean real-world trend.
B29: Performance and pay
B30: OBSERVATION | C30: Average salary generally rises with performance rating, from 66,320 at rating 1 up to 94,720 at rating 5 — except rating 2 (60,490) is slightly lower than rating 1's average.
B31: POSSIBLE EXPLANATION | C31: The general upward pattern suggests pay is loosely linked to performance in this dataset, but the rating-1-vs-2 dip is most likely just small-sample noise (only 9 and 31 employees respectively) rather than a real effect.
B33: Overtime prevalence
B34: OBSERVATION | C34: 37% of employees work overtime.
B35: POSSIBLE EXPLANATION | C35: N/A — a standalone figure worth tracking over time rather than explaining now.
